<robot name="pendulum">

    <material name="black">
        <color rgba="0 0 0 1"/>
    </material>

    <material name="white">
        <color rgba="1 1 1 1"/>
    </material>

    <material name="gray">
        <color rgba="0.4 0.4 0.4 1"/>
    </material>

    <material name="cyan">
        <color rgba="0 1.0 1.0 1.0"/>
        </material>

    <material name="purple">
        <color rgba="0.5 0 2.0 0.5"/>
        </material>


    <link name="world"/>
    <link name="base">
        <visual>
            <geometry>
                <sphere radius="0.1"/>
            </geometry>
            <material name="white"/>
        </visual>
        <inertial>
            <mass value="0"/>
            <inertia ixx="0"  ixy="0"  ixz="0" iyy="0" iyz="0" izz="0" />
        </inertial>
    </link>


    <link name="link_1">
        <visual>
            <geometry>
                <cylinder radius="0.01" length="0.8"/>
            </geometry>
            <origin xyz="0.0 0 0.4" rpy="0 0 0" />
            <material name="gray"/>
        </visual>
        <inertial>
            <mass value="0"/>
            <inertia ixx="0"  ixy="0"  ixz="0" iyy="0" iyz="0" izz="0" />
        </inertial>
    </link>

    <link name="link_eef1">
        <visual>
            <geometry>
                <sphere radius="0.05"/>
            </geometry>
            <origin xyz="0 0 0.05" rpy="0 0 0" />
            <material name="black"/>
        </visual>
        <inertial>
            <origin xyz="0 0 0" rpy="0 0 0"/>
            <mass value="2"/>
            <inertia ixx="0"  ixy="0"  ixz="0" iyy="0" iyz="0" izz="0" />
        </inertial>
    </link>

    <joint name="world_to_base" type="fixed">
        <parent link="world"/>
        <child link="base"/>
        <origin xyz="0 0 3.0" rpy="0 0 0"/>
    </joint>

    <joint name="joint_1" type="revolute">
        <parent link="base"/>
        <child link="link_1"/>
        <origin xyz="0.0 0 0" rpy="0 1.5707963267948966 0"/>
        <limit effort="0" velocity="0"/>
        <dynamics damping="1" friction="0"/>
        <axis xyz="0 -1 0"/>
    </joint>

    <joint name="joint_eef1" type="fixed">
        <parent link="link_1"/>
        <child link="link_eef1"/>
        <origin xyz="0 0 0.8" rpy="0 0 0"/>
    </joint>




    <link name="link_2">
        <visual>
            <geometry>
                <cylinder radius="0.01" length="0.7"/>
            </geometry>
            <origin xyz="0.0 0 0.35" rpy="0 0 0" />
            <material name="black"/>
        </visual>
        <inertial>
            <mass value="0"/>
            <inertia ixx="0"  ixy="0"  ixz="0" iyy="0" iyz="0" izz="0" />
        </inertial>
    </link>

    <link name="link_eef2">
        <visual>
            <geometry>
                <sphere radius="0.05"/>
            </geometry>
            <origin xyz="0 0 0.05" rpy="0 0 0" />
            <material name="black"/>
        </visual>
        <inertial>
            <origin xyz="0 0 0" rpy="0 0 0"/>
            <mass value="1.5"/>
            <inertia ixx="0"  ixy="0"  ixz="0" iyy="0" iyz="0" izz="0" />
        </inertial>
    </link>


    <joint name="joint_2" type="revolute">
        <parent link="link_eef1"/>
        <child link="link_2"/>
        <origin xyz="0.0 0 0" rpy="0 0 0"/>
        <limit effort="0" velocity="0"/>
        <dynamics damping="1" friction="0"/>
        <axis xyz="0 -1 0"/>
    </joint>

    <joint name="joint_eef2" type="fixed">
        <parent link="link_2"/>
        <child link="link_eef2"/>
        <origin xyz="0 0 0.7" rpy="0 0 0"/>
    </joint>


</robot>